2023-01-27 01:40:20,382 INFO ошибка = (1062, "Duplicate entry 'adeeer' for key 'mail'")
2023-01-27 01:40:20,453 INFO start_bot
2023-01-27 01:40:20,455 INFO Scheduler started
2023-01-27 01:41:26,239 INFO Received signal 2 (SIGINT), stopping...
2023-01-27 01:41:26,239 INFO Scheduler has been shut down
2023-01-27 01:41:26,526 WARNING Exiting immediately!
2023-01-27 02:01:09,176 INFO ошибка = (1062, "Duplicate entry 'adeeer' for key 'mail'")
2023-01-27 02:01:09,256 INFO start_bot
2023-01-27 02:01:09,258 INFO Scheduler started
2023-01-27 02:02:49,899 INFO Received signal 2 (SIGINT), stopping...
2023-01-27 02:02:49,899 INFO Scheduler has been shut down
2023-01-27 02:02:50,162 WARNING Exiting immediately!
2023-01-27 02:02:52,678 INFO ошибка = (1062, "Duplicate entry 'adeeer' for key 'mail'")
2023-01-27 02:02:52,757 INFO start_bot
2023-01-27 02:02:52,758 INFO Scheduler started
2023-01-27 02:02:58,191 ERROR No error handlers are registered, logging exception.
Traceback (most recent call last):
  File "/Library/Frameworks/Python.framework/Versions/3.11/lib/python3.11/site-packages/telegram/ext/dispatcher.py", line 557, in process_update
    handler.handle_update(update, self, check, context)
  File "/Library/Frameworks/Python.framework/Versions/3.11/lib/python3.11/site-packages/telegram/ext/handler.py", line 199, in handle_update
    return self.callback(update, context)
           ^^^^^^^^^^^^^^^^^^^^^^^^^^^^^^
  File "/Users/maksimbudanov/Documents/my_git/bot_telegram/my_folder/my_main.py", line 21, in echo
    update.message.reply_text('не понял:' + Update)
                              ~~~~~~~~~~~~^~~~~~~~
TypeError: can only concatenate str (not "type") to str
2023-01-27 02:03:08,079 ERROR No error handlers are registered, logging exception.
Traceback (most recent call last):
  File "/Library/Frameworks/Python.framework/Versions/3.11/lib/python3.11/site-packages/telegram/ext/dispatcher.py", line 557, in process_update
    handler.handle_update(update, self, check, context)
  File "/Library/Frameworks/Python.framework/Versions/3.11/lib/python3.11/site-packages/telegram/ext/handler.py", line 199, in handle_update
    return self.callback(update, context)
           ^^^^^^^^^^^^^^^^^^^^^^^^^^^^^^
  File "/Users/maksimbudanov/Documents/my_git/bot_telegram/my_folder/my_main.py", line 21, in echo
    update.message.reply_text('не понял:' + Update)
                              ~~~~~~~~~~~~^~~~~~~~
TypeError: can only concatenate str (not "type") to str
2023-01-27 02:03:17,395 ERROR No error handlers are registered, logging exception.
Traceback (most recent call last):
  File "/Library/Frameworks/Python.framework/Versions/3.11/lib/python3.11/site-packages/telegram/ext/dispatcher.py", line 557, in process_update
    handler.handle_update(update, self, check, context)
  File "/Library/Frameworks/Python.framework/Versions/3.11/lib/python3.11/site-packages/telegram/ext/handler.py", line 199, in handle_update
    return self.callback(update, context)
           ^^^^^^^^^^^^^^^^^^^^^^^^^^^^^^
  File "/Users/maksimbudanov/Documents/my_git/bot_telegram/my_folder/my_main.py", line 21, in echo
    update.message.reply_text('не понял:' + Update)
                              ~~~~~~~~~~~~^~~~~~~~
TypeError: can only concatenate str (not "type") to str
2023-01-27 02:04:24,136 INFO Received signal 2 (SIGINT), stopping...
2023-01-27 02:04:24,136 INFO Scheduler has been shut down
2023-01-27 02:04:24,383 WARNING Exiting immediately!
2023-01-27 02:04:27,141 INFO ошибка = (1062, "Duplicate entry 'adeeer' for key 'mail'")
2023-01-27 02:04:27,246 INFO start_bot
2023-01-27 02:04:27,247 INFO Scheduler started
2023-01-27 02:05:53,406 INFO Received signal 2 (SIGINT), stopping...
2023-01-27 02:05:53,406 INFO Scheduler has been shut down
2023-01-27 02:05:53,677 WARNING Exiting immediately!
2023-01-27 02:05:58,644 INFO ошибка = (1062, "Duplicate entry 'adeeer' for key 'mail'")
2023-01-27 02:05:58,727 INFO start_bot
2023-01-27 02:05:58,728 INFO Scheduler started
2023-01-27 02:07:00,180 INFO Received signal 2 (SIGINT), stopping...
2023-01-27 02:07:00,180 INFO Scheduler has been shut down
2023-01-27 02:07:00,452 WARNING Exiting immediately!
2023-01-27 02:07:07,607 INFO ошибка = (1062, "Duplicate entry 'adeeer' for key 'mail'")
2023-01-27 02:07:07,704 INFO start_bot
2023-01-27 02:07:07,705 INFO Scheduler started
2023-01-27 02:07:15,296 INFO d
2023-01-27 02:07:16,495 INFO d
2023-01-27 02:11:02,822 INFO Received signal 2 (SIGINT), stopping...
2023-01-27 02:11:02,822 INFO Scheduler has been shut down
2023-01-27 02:11:03,396 WARNING Exiting immediately!
2023-01-27 02:11:06,435 INFO ошибка = (1062, "Duplicate entry 'adeeer' for key 'mail'")
2023-01-27 02:11:06,509 INFO start_bot
2023-01-27 02:11:06,511 INFO Scheduler started
2023-01-27 02:11:11,927 ERROR No error handlers are registered, logging exception.
Traceback (most recent call last):
  File "/Library/Frameworks/Python.framework/Versions/3.11/lib/python3.11/site-packages/telegram/ext/dispatcher.py", line 557, in process_update
    handler.handle_update(update, self, check, context)
  File "/Library/Frameworks/Python.framework/Versions/3.11/lib/python3.11/site-packages/telegram/ext/handler.py", line 199, in handle_update
    return self.callback(update, context)
           ^^^^^^^^^^^^^^^^^^^^^^^^^^^^^^
  File "/Users/maksimbudanov/Documents/my_git/bot_telegram/my_folder/my_main.py", line 23, in echo
    print(update.chat.username)
          ^^^^^^^^^^^
AttributeError: 'Update' object has no attribute 'chat'
2023-01-27 02:14:39,652 INFO Received signal 2 (SIGINT), stopping...
2023-01-27 02:14:39,653 INFO Scheduler has been shut down
2023-01-27 02:14:40,083 WARNING Exiting immediately!
2023-01-27 02:14:43,135 INFO ошибка = (1062, "Duplicate entry 'adeeer' for key 'mail'")
2023-01-27 02:14:43,215 INFO start_bot
2023-01-27 02:14:43,217 INFO Scheduler started
2023-01-27 02:14:48,147 INFO d
2023-01-27 02:16:28,759 INFO Received signal 2 (SIGINT), stopping...
2023-01-27 02:16:28,759 INFO Scheduler has been shut down
2023-01-27 02:16:29,078 WARNING Exiting immediately!
2023-01-27 02:16:31,722 INFO ошибка = (1062, "Duplicate entry 'adeeer' for key 'mail'")
2023-01-27 02:16:31,802 INFO start_bot
2023-01-27 02:16:31,803 INFO Scheduler started
2023-01-27 02:16:36,510 INFO d
2023-01-27 02:17:19,732 INFO Received signal 2 (SIGINT), stopping...
2023-01-27 02:17:19,733 INFO Scheduler has been shut down
2023-01-27 02:17:19,948 WARNING Exiting immediately!
2023-01-27 02:17:23,798 INFO ошибка = (1062, "Duplicate entry 'adeeer' for key 'mail'")
2023-01-27 02:17:23,883 INFO start_bot
2023-01-27 02:17:23,884 INFO Scheduler started
2023-01-27 02:17:28,621 INFO None
2023-01-27 02:17:31,199 INFO None
2023-01-27 02:17:48,259 INFO Received signal 2 (SIGINT), stopping...
2023-01-27 02:17:48,260 INFO Scheduler has been shut down
2023-01-27 02:17:48,467 WARNING Exiting immediately!
2023-01-27 02:18:42,804 INFO ошибка = (1062, "Duplicate entry 'adeeer' for key 'mail'")
2023-01-27 02:18:42,888 INFO start_bot
2023-01-27 02:18:42,889 INFO Scheduler started
2023-01-27 02:18:46,102 INFO izbalkona : d
2023-01-27 02:19:32,479 INFO Received signal 2 (SIGINT), stopping...
2023-01-27 02:19:32,479 INFO Scheduler has been shut down
2023-01-27 02:19:32,758 WARNING Exiting immediately!
2023-01-27 02:19:36,452 INFO ошибка = (1062, "Duplicate entry 'adeeer' for key 'mail'")
2023-01-27 02:19:36,645 INFO start_bot
2023-01-27 02:19:36,646 INFO Scheduler started
2023-01-27 02:19:44,389 INFO izbalkona : привет
2023-01-27 02:22:13,993 INFO Received signal 2 (SIGINT), stopping...
2023-01-27 02:22:13,993 INFO Scheduler has been shut down
2023-01-27 02:22:14,303 WARNING Exiting immediately!
2023-01-27 02:22:18,716 INFO ошибка = (1062, "Duplicate entry 'adeeer' for key 'mail'")
2023-01-27 02:22:18,795 INFO start_bot
2023-01-27 02:22:18,796 INFO Scheduler started
2023-01-27 02:22:25,701 INFO izbalkona : сс
2023-01-27 02:38:34,357 INFO Received signal 2 (SIGINT), stopping...
2023-01-27 02:38:34,358 INFO Scheduler has been shut down
2023-01-27 02:38:34,581 WARNING Exiting immediately!
2023-01-27 02:38:37,103 INFO start_bot
2023-01-27 02:38:37,104 INFO Scheduler started
2023-01-27 02:40:25,666 INFO Received signal 2 (SIGINT), stopping...
2023-01-27 02:40:25,666 INFO Scheduler has been shut down
2023-01-27 02:40:26,001 WARNING Exiting immediately!
2023-01-27 02:40:28,301 INFO start_bot
2023-01-27 02:40:28,302 INFO Scheduler started
2023-01-27 02:41:05,190 INFO Received signal 2 (SIGINT), stopping...
2023-01-27 02:41:05,190 INFO Scheduler has been shut down
2023-01-27 02:41:05,520 WARNING Exiting immediately!
2023-01-27 02:41:08,711 INFO start_bot
2023-01-27 02:41:08,713 INFO Scheduler started
2023-01-27 02:42:17,446 INFO Received signal 2 (SIGINT), stopping...
2023-01-27 02:42:17,446 INFO Scheduler has been shut down
2023-01-27 02:42:17,886 WARNING Exiting immediately!
2023-01-27 02:43:27,258 INFO start_bot
2023-01-27 02:43:27,259 INFO Scheduler started
2023-01-27 02:44:27,427 INFO Received signal 2 (SIGINT), stopping...
2023-01-27 02:44:27,427 INFO Scheduler has been shut down
2023-01-27 02:44:27,714 WARNING Exiting immediately!
2023-01-27 02:44:37,603 INFO start_bot
2023-01-27 02:44:37,604 INFO Scheduler started
2023-01-27 02:46:44,375 INFO Received signal 2 (SIGINT), stopping...
2023-01-27 02:46:44,375 INFO Scheduler has been shut down
2023-01-27 02:46:44,686 WARNING Exiting immediately!
2023-01-27 02:47:21,180 INFO start_bot
2023-01-27 02:47:21,181 INFO Scheduler started
2023-01-27 02:50:36,191 INFO Received signal 2 (SIGINT), stopping...
2023-01-27 02:50:36,191 INFO Scheduler has been shut down
2023-01-27 02:50:36,471 WARNING Exiting immediately!
2023-01-27 02:50:39,250 INFO start_bot
2023-01-27 02:50:39,251 INFO Scheduler started
2023-01-27 02:51:01,535 INFO Received signal 2 (SIGINT), stopping...
2023-01-27 02:51:01,535 INFO Scheduler has been shut down
2023-01-27 02:51:01,870 WARNING Exiting immediately!
2023-01-27 02:51:04,516 INFO start_bot
2023-01-27 02:51:04,517 INFO Scheduler started
2023-01-27 02:51:25,430 INFO Received signal 2 (SIGINT), stopping...
2023-01-27 02:51:25,430 INFO Scheduler has been shut down
2023-01-27 02:51:25,725 WARNING Exiting immediately!
2023-01-27 02:52:09,578 INFO start_bot
2023-01-27 02:52:09,579 INFO Scheduler started
2023-01-27 02:54:07,514 INFO Received signal 2 (SIGINT), stopping...
2023-01-27 02:54:07,514 INFO Scheduler has been shut down
2023-01-27 02:54:07,777 WARNING Exiting immediately!
2023-01-27 02:54:12,140 INFO ошибка = (1062, "Duplicate entry 'adeeer' for key 'mail'")
2023-01-27 02:54:12,215 INFO start_bot
2023-01-27 02:54:12,216 INFO Scheduler started
2023-01-27 02:56:27,654 INFO Received signal 2 (SIGINT), stopping...
2023-01-27 02:56:27,654 INFO Scheduler has been shut down
2023-01-27 02:56:28,053 WARNING Exiting immediately!
2023-01-27 02:56:30,607 INFO start_bot
2023-01-27 02:56:30,608 INFO Scheduler started
2023-01-27 02:56:39,549 INFO Received signal 2 (SIGINT), stopping...
2023-01-27 02:56:39,549 INFO Scheduler has been shut down
2023-01-27 02:56:39,852 WARNING Exiting immediately!
2023-01-27 02:56:43,302 INFO start_bot
2023-01-27 02:56:43,304 INFO Scheduler started
2023-01-27 02:56:51,468 INFO Received signal 2 (SIGINT), stopping...
2023-01-27 02:56:51,468 INFO Scheduler has been shut down
2023-01-27 02:56:51,853 WARNING Exiting immediately!
2023-01-27 02:56:54,401 INFO ошибка = (1062, "Duplicate entry 'adeeer' for key 'mail'")
2023-01-27 02:56:54,491 INFO start_bot
2023-01-27 02:56:54,492 INFO Scheduler started
2023-01-27 03:03:09,349 INFO Received signal 2 (SIGINT), stopping...
2023-01-27 03:03:09,349 INFO Scheduler has been shut down
2023-01-27 03:03:09,645 WARNING Exiting immediately!
2023-01-27 03:03:31,693 INFO ошибка = (1062, "Duplicate entry 'adeeer' for key 'mail'")
2023-01-27 03:03:31,771 INFO start_bot
2023-01-27 03:03:31,773 INFO Scheduler started
2023-01-27 03:05:50,343 INFO Received signal 2 (SIGINT), stopping...
2023-01-27 03:05:50,343 INFO Scheduler has been shut down
2023-01-27 03:05:50,622 WARNING Exiting immediately!
2023-01-27 03:05:53,425 INFO ошибка = (1062, "Duplicate entry 'adeeer' for key 'mail'")
2023-01-27 03:05:53,502 INFO start_bot
2023-01-27 03:05:53,503 INFO Scheduler started
2023-01-27 03:06:04,424 ERROR No error handlers are registered, logging exception.
Traceback (most recent call last):
  File "/Library/Frameworks/Python.framework/Versions/3.11/lib/python3.11/site-packages/telegram/ext/dispatcher.py", line 557, in process_update
    handler.handle_update(update, self, check, context)
  File "/Library/Frameworks/Python.framework/Versions/3.11/lib/python3.11/site-packages/telegram/ext/handler.py", line 199, in handle_update
    return self.callback(update, context)
           ^^^^^^^^^^^^^^^^^^^^^^^^^^^^^^
  File "/Users/maksimbudanov/Documents/my_git/bot_telegram/my_folder/my_main.py", line 22, in echo
    ret = updater.dispatcher.add_handler(TypeHandler(Update))
                                         ^^^^^^^^^^^^^^^^^^^
TypeError: TypeHandler.__init__() missing 1 required positional argument: 'callback'
2023-01-27 03:06:56,996 INFO Received signal 2 (SIGINT), stopping...
2023-01-27 03:06:56,997 INFO Scheduler has been shut down
2023-01-27 03:06:57,276 WARNING Exiting immediately!
2023-01-27 03:06:59,505 INFO ошибка = (1062, "Duplicate entry 'adeeer' for key 'mail'")
2023-01-27 03:06:59,582 INFO start_bot
2023-01-27 03:06:59,584 INFO Scheduler started
2023-01-27 03:07:37,537 ERROR No error handlers are registered, logging exception.
Traceback (most recent call last):
  File "/Library/Frameworks/Python.framework/Versions/3.11/lib/python3.11/site-packages/telegram/ext/dispatcher.py", line 557, in process_update
    handler.handle_update(update, self, check, context)
  File "/Library/Frameworks/Python.framework/Versions/3.11/lib/python3.11/site-packages/telegram/ext/handler.py", line 199, in handle_update
    return self.callback(update, context)
           ^^^^^^^^^^^^^^^^^^^^^^^^^^^^^^
  File "/Users/maksimbudanov/Documents/my_git/bot_telegram/my_folder/my_main.py", line 22, in echo
    updater.dispatcher.add_handler(TypeHandler(Update))
                                   ^^^^^^^^^^^^^^^^^^^
TypeError: TypeHandler.__init__() missing 1 required positional argument: 'callback'
2023-01-27 03:08:26,921 INFO Received signal 2 (SIGINT), stopping...
2023-01-27 03:08:26,921 INFO Scheduler has been shut down
2023-01-27 03:08:27,337 WARNING Exiting immediately!
2023-01-27 03:08:31,280 INFO ошибка = (1062, "Duplicate entry 'adeeer' for key 'mail'")
2023-01-27 03:08:31,368 INFO start_bot
2023-01-27 03:08:31,369 INFO Scheduler started
2023-01-27 03:08:45,633 ERROR No error handlers are registered, logging exception.
Traceback (most recent call last):
  File "/Library/Frameworks/Python.framework/Versions/3.11/lib/python3.11/site-packages/telegram/ext/dispatcher.py", line 557, in process_update
    handler.handle_update(update, self, check, context)
  File "/Library/Frameworks/Python.framework/Versions/3.11/lib/python3.11/site-packages/telegram/ext/handler.py", line 199, in handle_update
    return self.callback(update, context)
           ^^^^^^^^^^^^^^^^^^^^^^^^^^^^^^
  File "/Users/maksimbudanov/Documents/my_git/bot_telegram/my_folder/my_main.py", line 22, in echo
    updater.dispatcher.add_handler(TypeHandler(Update))
                                   ^^^^^^^^^^^^^^^^^^^
TypeError: TypeHandler.__init__() missing 1 required positional argument: 'callback'
2023-01-27 03:09:16,583 INFO Received signal 2 (SIGINT), stopping...
2023-01-27 03:09:16,583 INFO Scheduler has been shut down
2023-01-27 03:09:16,895 WARNING Exiting immediately!
2023-01-27 03:09:23,645 INFO ошибка = (1062, "Duplicate entry 'adeeer' for key 'mail'")
2023-01-27 03:09:23,731 INFO start_bot
2023-01-27 03:09:23,732 INFO Scheduler started
2023-01-27 03:09:32,630 ERROR No error handlers are registered, logging exception.
Traceback (most recent call last):
  File "/Library/Frameworks/Python.framework/Versions/3.11/lib/python3.11/site-packages/telegram/ext/dispatcher.py", line 557, in process_update
    handler.handle_update(update, self, check, context)
  File "/Library/Frameworks/Python.framework/Versions/3.11/lib/python3.11/site-packages/telegram/ext/handler.py", line 199, in handle_update
    return self.callback(update, context)
           ^^^^^^^^^^^^^^^^^^^^^^^^^^^^^^
  File "/Users/maksimbudanov/Documents/my_git/bot_telegram/my_folder/my_main.py", line 23, in echo
    updater.dispatcher.add_handler(TypeHandler(Update))
                                   ^^^^^^^^^^^^^^^^^^^
TypeError: TypeHandler.__init__() missing 1 required positional argument: 'callback'
2023-01-27 05:15:57,078 ERROR No error handlers are registered, logging exception.
Traceback (most recent call last):
  File "/Library/Frameworks/Python.framework/Versions/3.11/lib/python3.11/site-packages/telegram/vendor/ptb_urllib3/urllib3/connectionpool.py", line 614, in urlopen
    httplib_response = self._make_request(conn, method, url,
                       ^^^^^^^^^^^^^^^^^^^^^^^^^^^^^^^^^^^^^
  File "/Library/Frameworks/Python.framework/Versions/3.11/lib/python3.11/site-packages/telegram/vendor/ptb_urllib3/urllib3/connectionpool.py", line 402, in _make_request
    six.raise_from(e, None)
  File "<string>", line 2, in raise_from
  File "/Library/Frameworks/Python.framework/Versions/3.11/lib/python3.11/site-packages/telegram/vendor/ptb_urllib3/urllib3/connectionpool.py", line 398, in _make_request
    httplib_response = conn.getresponse()
                       ^^^^^^^^^^^^^^^^^^
  File "/Library/Frameworks/Python.framework/Versions/3.11/lib/python3.11/http/client.py", line 1374, in getresponse
    response.begin()
  File "/Library/Frameworks/Python.framework/Versions/3.11/lib/python3.11/http/client.py", line 318, in begin
    version, status, reason = self._read_status()
                              ^^^^^^^^^^^^^^^^^^^
  File "/Library/Frameworks/Python.framework/Versions/3.11/lib/python3.11/http/client.py", line 287, in _read_status
    raise RemoteDisconnected("Remote end closed connection without"
http.client.RemoteDisconnected: Remote end closed connection without response

During handling of the above exception, another exception occurred:

Traceback (most recent call last):
  File "/Library/Frameworks/Python.framework/Versions/3.11/lib/python3.11/site-packages/telegram/utils/request.py", line 259, in _request_wrapper
    resp = self._con_pool.request(*args, **kwargs)
           ^^^^^^^^^^^^^^^^^^^^^^^^^^^^^^^^^^^^^^^
  File "/Library/Frameworks/Python.framework/Versions/3.11/lib/python3.11/site-packages/telegram/vendor/ptb_urllib3/urllib3/request.py", line 68, in request
    return self.request_encode_body(method, url, fields=fields,
           ^^^^^^^^^^^^^^^^^^^^^^^^^^^^^^^^^^^^^^^^^^^^^^^^^^^^
  File "/Library/Frameworks/Python.framework/Versions/3.11/lib/python3.11/site-packages/telegram/vendor/ptb_urllib3/urllib3/request.py", line 148, in request_encode_body
    return self.urlopen(method, url, **extra_kw)
           ^^^^^^^^^^^^^^^^^^^^^^^^^^^^^^^^^^^^^
  File "/Library/Frameworks/Python.framework/Versions/3.11/lib/python3.11/site-packages/telegram/vendor/ptb_urllib3/urllib3/poolmanager.py", line 244, in urlopen
    response = conn.urlopen(method, u.request_uri, **kw)
               ^^^^^^^^^^^^^^^^^^^^^^^^^^^^^^^^^^^^^^^^^
  File "/Library/Frameworks/Python.framework/Versions/3.11/lib/python3.11/site-packages/telegram/vendor/ptb_urllib3/urllib3/connectionpool.py", line 665, in urlopen
    retries = retries.increment(method, url, error=e, _pool=self,
              ^^^^^^^^^^^^^^^^^^^^^^^^^^^^^^^^^^^^^^^^^^^^^^^^^^^
  File "/Library/Frameworks/Python.framework/Versions/3.11/lib/python3.11/site-packages/telegram/vendor/ptb_urllib3/urllib3/util/retry.py", line 347, in increment
    raise six.reraise(type(error), error, _stacktrace)
          ^^^^^^^^^^^^^^^^^^^^^^^^^^^^^^^^^^^^^^^^^^^^
  File "/Library/Frameworks/Python.framework/Versions/3.11/lib/python3.11/site-packages/telegram/vendor/ptb_urllib3/urllib3/packages/six.py", line 685, in reraise
    raise value.with_traceback(tb)
  File "/Library/Frameworks/Python.framework/Versions/3.11/lib/python3.11/site-packages/telegram/vendor/ptb_urllib3/urllib3/connectionpool.py", line 614, in urlopen
    httplib_response = self._make_request(conn, method, url,
                       ^^^^^^^^^^^^^^^^^^^^^^^^^^^^^^^^^^^^^
  File "/Library/Frameworks/Python.framework/Versions/3.11/lib/python3.11/site-packages/telegram/vendor/ptb_urllib3/urllib3/connectionpool.py", line 402, in _make_request
    six.raise_from(e, None)
  File "<string>", line 2, in raise_from
  File "/Library/Frameworks/Python.framework/Versions/3.11/lib/python3.11/site-packages/telegram/vendor/ptb_urllib3/urllib3/connectionpool.py", line 398, in _make_request
    httplib_response = conn.getresponse()
                       ^^^^^^^^^^^^^^^^^^
  File "/Library/Frameworks/Python.framework/Versions/3.11/lib/python3.11/http/client.py", line 1374, in getresponse
    response.begin()
  File "/Library/Frameworks/Python.framework/Versions/3.11/lib/python3.11/http/client.py", line 318, in begin
    version, status, reason = self._read_status()
                              ^^^^^^^^^^^^^^^^^^^
  File "/Library/Frameworks/Python.framework/Versions/3.11/lib/python3.11/http/client.py", line 287, in _read_status
    raise RemoteDisconnected("Remote end closed connection without"
telegram.vendor.ptb_urllib3.urllib3.exceptions.ProtocolError: ('Connection aborted.', RemoteDisconnected('Remote end closed connection without response'))

The above exception was the direct cause of the following exception:

Traceback (most recent call last):
  File "/Library/Frameworks/Python.framework/Versions/3.11/lib/python3.11/site-packages/telegram/ext/dispatcher.py", line 557, in process_update
    handler.handle_update(update, self, check, context)
  File "/Library/Frameworks/Python.framework/Versions/3.11/lib/python3.11/site-packages/telegram/ext/handler.py", line 199, in handle_update
    return self.callback(update, context)
           ^^^^^^^^^^^^^^^^^^^^^^^^^^^^^^
  File "/Users/maksimbudanov/Documents/my_git/bot_telegram/my_folder/my_main.py", line 29, in echo
    def main() -> None:
            ^^^^^^^^^^^^
  File "/Library/Frameworks/Python.framework/Versions/3.11/lib/python3.11/site-packages/telegram/message.py", line 912, in reply_text
    return self.bot.send_message(
           ^^^^^^^^^^^^^^^^^^^^^^
  File "/Library/Frameworks/Python.framework/Versions/3.11/lib/python3.11/site-packages/telegram/bot.py", line 133, in decorator
    result = func(*args, **kwargs)
             ^^^^^^^^^^^^^^^^^^^^^
  File "/Library/Frameworks/Python.framework/Versions/3.11/lib/python3.11/site-packages/telegram/bot.py", line 525, in send_message
    return self._message(  # type: ignore[return-value]
           ^^^^^^^^^^^^^^^^^^^^^^^^^^^^^^^^^^^^^^^^^^^^
  File "/Library/Frameworks/Python.framework/Versions/3.11/lib/python3.11/site-packages/telegram/ext/extbot.py", line 202, in _message
    result = super()._message(
             ^^^^^^^^^^^^^^^^^
  File "/Library/Frameworks/Python.framework/Versions/3.11/lib/python3.11/site-packages/telegram/bot.py", line 339, in _message
    result = self._post(endpoint, data, timeout=timeout, api_kwargs=api_kwargs)
             ^^^^^^^^^^^^^^^^^^^^^^^^^^^^^^^^^^^^^^^^^^^^^^^^^^^^^^^^^^^^^^^^^^
  File "/Library/Frameworks/Python.framework/Versions/3.11/lib/python3.11/site-packages/telegram/bot.py", line 298, in _post
    return self.request.post(
           ^^^^^^^^^^^^^^^^^^
  File "/Library/Frameworks/Python.framework/Versions/3.11/lib/python3.11/site-packages/telegram/utils/request.py", line 361, in post
    result = self._request_wrapper(
             ^^^^^^^^^^^^^^^^^^^^^^
  File "/Library/Frameworks/Python.framework/Versions/3.11/lib/python3.11/site-packages/telegram/utils/request.py", line 265, in _request_wrapper
    raise NetworkError(f'urllib3 HTTPError {error}') from error
telegram.error.NetworkError: urllib3 HTTPError ('Connection aborted.', RemoteDisconnected('Remote end closed connection without response'))
2023-01-27 05:15:57,909 ERROR No error handlers are registered, logging exception.
Traceback (most recent call last):
  File "/Library/Frameworks/Python.framework/Versions/3.11/lib/python3.11/site-packages/telegram/vendor/ptb_urllib3/urllib3/connectionpool.py", line 614, in urlopen
    httplib_response = self._make_request(conn, method, url,
                       ^^^^^^^^^^^^^^^^^^^^^^^^^^^^^^^^^^^^^
  File "/Library/Frameworks/Python.framework/Versions/3.11/lib/python3.11/site-packages/telegram/vendor/ptb_urllib3/urllib3/connectionpool.py", line 402, in _make_request
    six.raise_from(e, None)
  File "<string>", line 2, in raise_from
  File "/Library/Frameworks/Python.framework/Versions/3.11/lib/python3.11/site-packages/telegram/vendor/ptb_urllib3/urllib3/connectionpool.py", line 398, in _make_request
    httplib_response = conn.getresponse()
                       ^^^^^^^^^^^^^^^^^^
  File "/Library/Frameworks/Python.framework/Versions/3.11/lib/python3.11/http/client.py", line 1374, in getresponse
    response.begin()
  File "/Library/Frameworks/Python.framework/Versions/3.11/lib/python3.11/http/client.py", line 318, in begin
    version, status, reason = self._read_status()
                              ^^^^^^^^^^^^^^^^^^^
  File "/Library/Frameworks/Python.framework/Versions/3.11/lib/python3.11/http/client.py", line 287, in _read_status
    raise RemoteDisconnected("Remote end closed connection without"
http.client.RemoteDisconnected: Remote end closed connection without response

During handling of the above exception, another exception occurred:

Traceback (most recent call last):
  File "/Library/Frameworks/Python.framework/Versions/3.11/lib/python3.11/site-packages/telegram/utils/request.py", line 259, in _request_wrapper
    resp = self._con_pool.request(*args, **kwargs)
           ^^^^^^^^^^^^^^^^^^^^^^^^^^^^^^^^^^^^^^^
  File "/Library/Frameworks/Python.framework/Versions/3.11/lib/python3.11/site-packages/telegram/vendor/ptb_urllib3/urllib3/request.py", line 68, in request
    return self.request_encode_body(method, url, fields=fields,
           ^^^^^^^^^^^^^^^^^^^^^^^^^^^^^^^^^^^^^^^^^^^^^^^^^^^^
  File "/Library/Frameworks/Python.framework/Versions/3.11/lib/python3.11/site-packages/telegram/vendor/ptb_urllib3/urllib3/request.py", line 148, in request_encode_body
    return self.urlopen(method, url, **extra_kw)
           ^^^^^^^^^^^^^^^^^^^^^^^^^^^^^^^^^^^^^
  File "/Library/Frameworks/Python.framework/Versions/3.11/lib/python3.11/site-packages/telegram/vendor/ptb_urllib3/urllib3/poolmanager.py", line 244, in urlopen
    response = conn.urlopen(method, u.request_uri, **kw)
               ^^^^^^^^^^^^^^^^^^^^^^^^^^^^^^^^^^^^^^^^^
  File "/Library/Frameworks/Python.framework/Versions/3.11/lib/python3.11/site-packages/telegram/vendor/ptb_urllib3/urllib3/connectionpool.py", line 665, in urlopen
    retries = retries.increment(method, url, error=e, _pool=self,
              ^^^^^^^^^^^^^^^^^^^^^^^^^^^^^^^^^^^^^^^^^^^^^^^^^^^
  File "/Library/Frameworks/Python.framework/Versions/3.11/lib/python3.11/site-packages/telegram/vendor/ptb_urllib3/urllib3/util/retry.py", line 347, in increment
    raise six.reraise(type(error), error, _stacktrace)
          ^^^^^^^^^^^^^^^^^^^^^^^^^^^^^^^^^^^^^^^^^^^^
  File "/Library/Frameworks/Python.framework/Versions/3.11/lib/python3.11/site-packages/telegram/vendor/ptb_urllib3/urllib3/packages/six.py", line 685, in reraise
    raise value.with_traceback(tb)
  File "/Library/Frameworks/Python.framework/Versions/3.11/lib/python3.11/site-packages/telegram/vendor/ptb_urllib3/urllib3/connectionpool.py", line 614, in urlopen
    httplib_response = self._make_request(conn, method, url,
                       ^^^^^^^^^^^^^^^^^^^^^^^^^^^^^^^^^^^^^
  File "/Library/Frameworks/Python.framework/Versions/3.11/lib/python3.11/site-packages/telegram/vendor/ptb_urllib3/urllib3/connectionpool.py", line 402, in _make_request
    six.raise_from(e, None)
  File "<string>", line 2, in raise_from
  File "/Library/Frameworks/Python.framework/Versions/3.11/lib/python3.11/site-packages/telegram/vendor/ptb_urllib3/urllib3/connectionpool.py", line 398, in _make_request
    httplib_response = conn.getresponse()
                       ^^^^^^^^^^^^^^^^^^
  File "/Library/Frameworks/Python.framework/Versions/3.11/lib/python3.11/http/client.py", line 1374, in getresponse
    response.begin()
  File "/Library/Frameworks/Python.framework/Versions/3.11/lib/python3.11/http/client.py", line 318, in begin
    version, status, reason = self._read_status()
                              ^^^^^^^^^^^^^^^^^^^
  File "/Library/Frameworks/Python.framework/Versions/3.11/lib/python3.11/http/client.py", line 287, in _read_status
    raise RemoteDisconnected("Remote end closed connection without"
telegram.vendor.ptb_urllib3.urllib3.exceptions.ProtocolError: ('Connection aborted.', RemoteDisconnected('Remote end closed connection without response'))

The above exception was the direct cause of the following exception:

Traceback (most recent call last):
  File "/Library/Frameworks/Python.framework/Versions/3.11/lib/python3.11/site-packages/telegram/ext/dispatcher.py", line 557, in process_update
    handler.handle_update(update, self, check, context)
  File "/Library/Frameworks/Python.framework/Versions/3.11/lib/python3.11/site-packages/telegram/ext/handler.py", line 199, in handle_update
    return self.callback(update, context)
           ^^^^^^^^^^^^^^^^^^^^^^^^^^^^^^
  File "/Users/maksimbudanov/Documents/my_git/bot_telegram/my_folder/my_main.py", line 21, in echo
    tprint('Укажите ваш логин: ')
  File "/Users/maksimbudanov/Documents/my_git/bot_telegram/my_folder/my_main_bible.py", line 24, in tprint
    bot.send_message(chat_id, saw)
  File "/Library/Frameworks/Python.framework/Versions/3.11/lib/python3.11/site-packages/telegram/bot.py", line 133, in decorator
    result = func(*args, **kwargs)
             ^^^^^^^^^^^^^^^^^^^^^
  File "/Library/Frameworks/Python.framework/Versions/3.11/lib/python3.11/site-packages/telegram/bot.py", line 525, in send_message
    return self._message(  # type: ignore[return-value]
           ^^^^^^^^^^^^^^^^^^^^^^^^^^^^^^^^^^^^^^^^^^^^
  File "/Library/Frameworks/Python.framework/Versions/3.11/lib/python3.11/site-packages/telegram/bot.py", line 339, in _message
    result = self._post(endpoint, data, timeout=timeout, api_kwargs=api_kwargs)
             ^^^^^^^^^^^^^^^^^^^^^^^^^^^^^^^^^^^^^^^^^^^^^^^^^^^^^^^^^^^^^^^^^^
  File "/Library/Frameworks/Python.framework/Versions/3.11/lib/python3.11/site-packages/telegram/bot.py", line 298, in _post
    return self.request.post(
           ^^^^^^^^^^^^^^^^^^
  File "/Library/Frameworks/Python.framework/Versions/3.11/lib/python3.11/site-packages/telegram/utils/request.py", line 361, in post
    result = self._request_wrapper(
             ^^^^^^^^^^^^^^^^^^^^^^
  File "/Library/Frameworks/Python.framework/Versions/3.11/lib/python3.11/site-packages/telegram/utils/request.py", line 265, in _request_wrapper
    raise NetworkError(f'urllib3 HTTPError {error}') from error
telegram.error.NetworkError: urllib3 HTTPError ('Connection aborted.', RemoteDisconnected('Remote end closed connection without response'))
2023-01-27 13:59:17,181 INFO Received signal 2 (SIGINT), stopping...
2023-01-27 13:59:17,181 INFO Scheduler has been shut down
2023-01-27 13:59:17,428 WARNING Exiting immediately!
2023-01-27 13:59:22,280 INFO ошибка = (1062, "Duplicate entry 'adeeer' for key 'mail'")
2023-01-27 13:59:22,364 INFO start_bot
2023-01-27 13:59:22,365 INFO Scheduler started
2023-01-27 13:59:35,252 INFO Received signal 2 (SIGINT), stopping...
2023-01-27 13:59:35,252 INFO Scheduler has been shut down
2023-01-27 13:59:35,540 WARNING Exiting immediately!
2023-01-27 14:00:38,286 INFO ошибка = (1062, "Duplicate entry 'adeeer' for key 'mail'")
2023-01-27 14:00:38,463 INFO start_bot
2023-01-27 14:00:38,464 INFO Scheduler started
2023-01-27 14:03:11,816 INFO Received signal 2 (SIGINT), stopping...
2023-01-27 14:03:11,816 INFO Scheduler has been shut down
2023-01-27 14:03:12,160 WARNING Exiting immediately!
2023-01-27 14:06:43,609 INFO ошибка = (1062, "Duplicate entry 'adeeer' for key 'mail'")
2023-01-27 14:06:43,695 INFO start_bot
2023-01-27 14:06:43,696 INFO Scheduler started
2023-01-27 14:06:48,860 ERROR No error handlers are registered, logging exception.
Traceback (most recent call last):
  File "/Library/Frameworks/Python.framework/Versions/3.11/lib/python3.11/site-packages/telegram/ext/dispatcher.py", line 557, in process_update
    handler.handle_update(update, self, check, context)
  File "/Library/Frameworks/Python.framework/Versions/3.11/lib/python3.11/site-packages/telegram/ext/handler.py", line 199, in handle_update
    return self.callback(update, context)
           ^^^^^^^^^^^^^^^^^^^^^^^^^^^^^^
  File "/Users/maksimbudanov/Documents/my_git/bot_telegram/my_folder/my_main.py", line 20, in echo
    tprint(f'Ваш <b>запрос - {update.message.text}</b> - не понятен для меня', parse_mode='html' )
TypeError: tprint() got an unexpected keyword argument 'parse_mode'
2023-01-27 14:06:53,528 ERROR No error handlers are registered, logging exception.
Traceback (most recent call last):
  File "/Library/Frameworks/Python.framework/Versions/3.11/lib/python3.11/site-packages/telegram/ext/dispatcher.py", line 557, in process_update
    handler.handle_update(update, self, check, context)
  File "/Library/Frameworks/Python.framework/Versions/3.11/lib/python3.11/site-packages/telegram/ext/handler.py", line 199, in handle_update
    return self.callback(update, context)
           ^^^^^^^^^^^^^^^^^^^^^^^^^^^^^^
  File "/Users/maksimbudanov/Documents/my_git/bot_telegram/my_folder/my_main.py", line 20, in echo
    tprint(f'Ваш <b>запрос - {update.message.text}</b> - не понятен для меня', parse_mode='html' )
TypeError: tprint() got an unexpected keyword argument 'parse_mode'
2023-01-27 14:13:55,644 INFO Received signal 2 (SIGINT), stopping...
2023-01-27 14:13:55,644 INFO Scheduler has been shut down
2023-01-27 14:13:55,939 WARNING Exiting immediately!
2023-01-27 14:13:58,531 INFO ошибка = (1062, "Duplicate entry 'adeeer' for key 'mail'")
2023-01-27 14:13:58,702 INFO start_bot
2023-01-27 14:13:58,703 INFO Scheduler started
2023-01-27 14:15:51,761 INFO Received signal 2 (SIGINT), stopping...
2023-01-27 14:15:51,761 INFO Scheduler has been shut down
2023-01-27 14:15:52,048 WARNING Exiting immediately!
2023-01-27 14:15:55,748 INFO ошибка = (1062, "Duplicate entry 'adeeer' for key 'mail'")
2023-01-27 14:15:55,838 INFO start_bot
2023-01-27 14:15:55,840 INFO Scheduler started
2023-01-27 14:15:59,704 ERROR No error handlers are registered, logging exception.
Traceback (most recent call last):
  File "/Library/Frameworks/Python.framework/Versions/3.11/lib/python3.11/site-packages/telegram/ext/dispatcher.py", line 557, in process_update
    handler.handle_update(update, self, check, context)
  File "/Library/Frameworks/Python.framework/Versions/3.11/lib/python3.11/site-packages/telegram/ext/handler.py", line 199, in handle_update
    return self.callback(update, context)
           ^^^^^^^^^^^^^^^^^^^^^^^^^^^^^^
  File "/Users/maksimbudanov/Documents/my_git/bot_telegram/my_folder/my_main.py", line 20, in echo
    tprint(f'Ваш запрос - <font color="blue"><b>{update.message.text}</b></font> - не понятен для меня')
  File "/Users/maksimbudanov/Documents/my_git/bot_telegram/my_folder/my_main_bible.py", line 24, in tprint
    bot.send_message(chat_id, saw,  parse_mode='html' )
  File "/Library/Frameworks/Python.framework/Versions/3.11/lib/python3.11/site-packages/telegram/bot.py", line 133, in decorator
    result = func(*args, **kwargs)
             ^^^^^^^^^^^^^^^^^^^^^
  File "/Library/Frameworks/Python.framework/Versions/3.11/lib/python3.11/site-packages/telegram/bot.py", line 525, in send_message
    return self._message(  # type: ignore[return-value]
           ^^^^^^^^^^^^^^^^^^^^^^^^^^^^^^^^^^^^^^^^^^^^
  File "/Library/Frameworks/Python.framework/Versions/3.11/lib/python3.11/site-packages/telegram/bot.py", line 339, in _message
    result = self._post(endpoint, data, timeout=timeout, api_kwargs=api_kwargs)
             ^^^^^^^^^^^^^^^^^^^^^^^^^^^^^^^^^^^^^^^^^^^^^^^^^^^^^^^^^^^^^^^^^^
  File "/Library/Frameworks/Python.framework/Versions/3.11/lib/python3.11/site-packages/telegram/bot.py", line 298, in _post
    return self.request.post(
           ^^^^^^^^^^^^^^^^^^
  File "/Library/Frameworks/Python.framework/Versions/3.11/lib/python3.11/site-packages/telegram/utils/request.py", line 361, in post
    result = self._request_wrapper(
             ^^^^^^^^^^^^^^^^^^^^^^
  File "/Library/Frameworks/Python.framework/Versions/3.11/lib/python3.11/site-packages/telegram/utils/request.py", line 279, in _request_wrapper
    raise BadRequest(message)
telegram.error.BadRequest: Can't parse entities: unsupported start tag "font" at byte offset 22
2023-01-27 14:16:40,919 INFO Received signal 2 (SIGINT), stopping...
2023-01-27 14:16:40,919 INFO Scheduler has been shut down
2023-01-27 14:16:41,230 WARNING Exiting immediately!
2023-01-27 14:16:43,250 INFO ошибка = (1062, "Duplicate entry 'adeeer' for key 'mail'")
2023-01-27 14:16:43,349 INFO start_bot
2023-01-27 14:16:43,351 INFO Scheduler started
2023-01-27 14:16:48,382 ERROR No error handlers are registered, logging exception.
Traceback (most recent call last):
  File "/Library/Frameworks/Python.framework/Versions/3.11/lib/python3.11/site-packages/telegram/ext/dispatcher.py", line 557, in process_update
    handler.handle_update(update, self, check, context)
  File "/Library/Frameworks/Python.framework/Versions/3.11/lib/python3.11/site-packages/telegram/ext/handler.py", line 199, in handle_update
    return self.callback(update, context)
           ^^^^^^^^^^^^^^^^^^^^^^^^^^^^^^
  File "/Users/maksimbudanov/Documents/my_git/bot_telegram/my_folder/my_main.py", line 20, in echo
    tprint(f'Ваш запрос - <font color="blue">{update.message.text}</font> - не понятен для меня')
  File "/Users/maksimbudanov/Documents/my_git/bot_telegram/my_folder/my_main_bible.py", line 24, in tprint
    bot.send_message(chat_id, saw,  parse_mode='html' )
  File "/Library/Frameworks/Python.framework/Versions/3.11/lib/python3.11/site-packages/telegram/bot.py", line 133, in decorator
    result = func(*args, **kwargs)
             ^^^^^^^^^^^^^^^^^^^^^
  File "/Library/Frameworks/Python.framework/Versions/3.11/lib/python3.11/site-packages/telegram/bot.py", line 525, in send_message
    return self._message(  # type: ignore[return-value]
           ^^^^^^^^^^^^^^^^^^^^^^^^^^^^^^^^^^^^^^^^^^^^
  File "/Library/Frameworks/Python.framework/Versions/3.11/lib/python3.11/site-packages/telegram/bot.py", line 339, in _message
    result = self._post(endpoint, data, timeout=timeout, api_kwargs=api_kwargs)
             ^^^^^^^^^^^^^^^^^^^^^^^^^^^^^^^^^^^^^^^^^^^^^^^^^^^^^^^^^^^^^^^^^^
  File "/Library/Frameworks/Python.framework/Versions/3.11/lib/python3.11/site-packages/telegram/bot.py", line 298, in _post
    return self.request.post(
           ^^^^^^^^^^^^^^^^^^
  File "/Library/Frameworks/Python.framework/Versions/3.11/lib/python3.11/site-packages/telegram/utils/request.py", line 361, in post
    result = self._request_wrapper(
             ^^^^^^^^^^^^^^^^^^^^^^
  File "/Library/Frameworks/Python.framework/Versions/3.11/lib/python3.11/site-packages/telegram/utils/request.py", line 279, in _request_wrapper
    raise BadRequest(message)
telegram.error.BadRequest: Can't parse entities: unsupported start tag "font" at byte offset 22
2023-01-27 14:16:50,102 ERROR No error handlers are registered, logging exception.
Traceback (most recent call last):
  File "/Library/Frameworks/Python.framework/Versions/3.11/lib/python3.11/site-packages/telegram/ext/dispatcher.py", line 557, in process_update
    handler.handle_update(update, self, check, context)
  File "/Library/Frameworks/Python.framework/Versions/3.11/lib/python3.11/site-packages/telegram/ext/handler.py", line 199, in handle_update
    return self.callback(update, context)
           ^^^^^^^^^^^^^^^^^^^^^^^^^^^^^^
  File "/Users/maksimbudanov/Documents/my_git/bot_telegram/my_folder/my_main.py", line 20, in echo
    tprint(f'Ваш запрос - <font color="blue">{update.message.text}</font> - не понятен для меня')
  File "/Users/maksimbudanov/Documents/my_git/bot_telegram/my_folder/my_main_bible.py", line 24, in tprint
    bot.send_message(chat_id, saw,  parse_mode='html' )
  File "/Library/Frameworks/Python.framework/Versions/3.11/lib/python3.11/site-packages/telegram/bot.py", line 133, in decorator
    result = func(*args, **kwargs)
             ^^^^^^^^^^^^^^^^^^^^^
  File "/Library/Frameworks/Python.framework/Versions/3.11/lib/python3.11/site-packages/telegram/bot.py", line 525, in send_message
    return self._message(  # type: ignore[return-value]
           ^^^^^^^^^^^^^^^^^^^^^^^^^^^^^^^^^^^^^^^^^^^^
  File "/Library/Frameworks/Python.framework/Versions/3.11/lib/python3.11/site-packages/telegram/bot.py", line 339, in _message
    result = self._post(endpoint, data, timeout=timeout, api_kwargs=api_kwargs)
             ^^^^^^^^^^^^^^^^^^^^^^^^^^^^^^^^^^^^^^^^^^^^^^^^^^^^^^^^^^^^^^^^^^
  File "/Library/Frameworks/Python.framework/Versions/3.11/lib/python3.11/site-packages/telegram/bot.py", line 298, in _post
    return self.request.post(
           ^^^^^^^^^^^^^^^^^^
  File "/Library/Frameworks/Python.framework/Versions/3.11/lib/python3.11/site-packages/telegram/utils/request.py", line 361, in post
    result = self._request_wrapper(
             ^^^^^^^^^^^^^^^^^^^^^^
  File "/Library/Frameworks/Python.framework/Versions/3.11/lib/python3.11/site-packages/telegram/utils/request.py", line 279, in _request_wrapper
    raise BadRequest(message)
telegram.error.BadRequest: Can't parse entities: unsupported start tag "font" at byte offset 22
2023-01-27 14:17:20,741 INFO Received signal 2 (SIGINT), stopping...
2023-01-27 14:17:20,742 INFO Scheduler has been shut down
2023-01-27 14:17:21,037 WARNING Exiting immediately!
2023-01-27 14:17:22,886 INFO ошибка = (1062, "Duplicate entry 'adeeer' for key 'mail'")
2023-01-27 14:17:22,982 INFO start_bot
2023-01-27 14:17:22,984 INFO Scheduler started
2023-01-27 14:17:26,820 ERROR No error handlers are registered, logging exception.
Traceback (most recent call last):
  File "/Library/Frameworks/Python.framework/Versions/3.11/lib/python3.11/site-packages/telegram/ext/dispatcher.py", line 557, in process_update
    handler.handle_update(update, self, check, context)
  File "/Library/Frameworks/Python.framework/Versions/3.11/lib/python3.11/site-packages/telegram/ext/handler.py", line 199, in handle_update
    return self.callback(update, context)
           ^^^^^^^^^^^^^^^^^^^^^^^^^^^^^^
  File "/Users/maksimbudanov/Documents/my_git/bot_telegram/my_folder/my_main.py", line 20, in echo
    tprint(f'Ваш запрос - <p style="color:#0000FF">{update.message.text}</p> - не понятен для меня')
  File "/Users/maksimbudanov/Documents/my_git/bot_telegram/my_folder/my_main_bible.py", line 24, in tprint
    bot.send_message(chat_id, saw,  parse_mode='html' )
  File "/Library/Frameworks/Python.framework/Versions/3.11/lib/python3.11/site-packages/telegram/bot.py", line 133, in decorator
    result = func(*args, **kwargs)
             ^^^^^^^^^^^^^^^^^^^^^
  File "/Library/Frameworks/Python.framework/Versions/3.11/lib/python3.11/site-packages/telegram/bot.py", line 525, in send_message
    return self._message(  # type: ignore[return-value]
           ^^^^^^^^^^^^^^^^^^^^^^^^^^^^^^^^^^^^^^^^^^^^
  File "/Library/Frameworks/Python.framework/Versions/3.11/lib/python3.11/site-packages/telegram/bot.py", line 339, in _message
    result = self._post(endpoint, data, timeout=timeout, api_kwargs=api_kwargs)
             ^^^^^^^^^^^^^^^^^^^^^^^^^^^^^^^^^^^^^^^^^^^^^^^^^^^^^^^^^^^^^^^^^^
  File "/Library/Frameworks/Python.framework/Versions/3.11/lib/python3.11/site-packages/telegram/bot.py", line 298, in _post
    return self.request.post(
           ^^^^^^^^^^^^^^^^^^
  File "/Library/Frameworks/Python.framework/Versions/3.11/lib/python3.11/site-packages/telegram/utils/request.py", line 361, in post
    result = self._request_wrapper(
             ^^^^^^^^^^^^^^^^^^^^^^
  File "/Library/Frameworks/Python.framework/Versions/3.11/lib/python3.11/site-packages/telegram/utils/request.py", line 279, in _request_wrapper
    raise BadRequest(message)
telegram.error.BadRequest: Can't parse entities: unsupported start tag "p" at byte offset 22
2023-01-27 14:21:26,478 INFO Received signal 2 (SIGINT), stopping...
2023-01-27 14:21:26,478 INFO Scheduler has been shut down
2023-01-27 14:21:26,750 WARNING Exiting immediately!
2023-01-27 14:21:29,428 INFO ошибка = (1062, "Duplicate entry 'adeeer' for key 'mail'")
2023-01-27 14:21:29,516 INFO start_bot
2023-01-27 14:21:29,517 INFO Scheduler started
2023-01-27 14:22:02,702 INFO Received signal 2 (SIGINT), stopping...
2023-01-27 14:22:02,702 INFO Scheduler has been shut down
2023-01-27 14:22:02,917 WARNING Exiting immediately!
2023-01-27 14:22:07,329 INFO ошибка = (1062, "Duplicate entry 'adeeer' for key 'mail'")
2023-01-27 14:22:07,417 INFO start_bot
2023-01-27 14:22:07,418 INFO Scheduler started
2023-01-27 14:48:21,735 INFO Received signal 2 (SIGINT), stopping...
2023-01-27 14:48:21,735 INFO Scheduler has been shut down
2023-01-27 14:48:21,983 WARNING Exiting immediately!
2023-01-27 15:14:03,973 INFO ошибка = (1062, "Duplicate entry 'adeeer' for key 'mail'")
2023-01-27 15:14:04,065 INFO start_bot
2023-01-27 15:14:04,067 INFO Scheduler started
2023-01-27 15:18:37,512 INFO Received signal 2 (SIGINT), stopping...
2023-01-27 15:18:37,513 INFO Scheduler has been shut down
2023-01-27 15:18:37,737 WARNING Exiting immediately!
2023-01-27 15:18:40,978 INFO start_bot
2023-01-27 15:18:40,979 INFO Scheduler started
2023-01-27 15:19:09,647 INFO нераспознанный текст d
2023-01-27 15:19:53,957 INFO Received signal 2 (SIGINT), stopping...
2023-01-27 15:19:53,957 INFO Scheduler has been shut down
2023-01-27 15:19:54,309 WARNING Exiting immediately!
2023-01-27 15:19:56,761 INFO start_bot--------------------
2023-01-27 15:19:56,762 INFO Scheduler started
2023-01-27 15:20:02,624 INFO нераспознанный текст d
2023-01-27 15:20:22,421 INFO Received signal 2 (SIGINT), stopping...
2023-01-27 15:20:22,421 INFO Scheduler has been shut down
2023-01-27 15:20:22,740 WARNING Exiting immediately!
2023-01-27 15:23:41,246 INFO start_bot--------------------
2023-01-27 15:23:41,247 INFO Scheduler started
2023-01-27 15:25:17,922 INFO Received signal 2 (SIGINT), stopping...
2023-01-27 15:25:17,924 INFO Scheduler has been shut down
2023-01-27 15:25:18,250 WARNING Exiting immediately!
2023-01-27 15:25:27,753 INFO start_bot--------------------
2023-01-27 15:25:27,754 INFO Scheduler started
2023-01-27 15:27:12,290 INFO Received signal 2 (SIGINT), stopping...
2023-01-27 15:27:12,291 INFO Scheduler has been shut down
2023-01-27 15:27:12,538 WARNING Exiting immediately!
2023-01-27 15:27:19,833 INFO start_bot--------------------
2023-01-27 15:27:19,834 INFO Scheduler started
2023-01-27 15:30:35,161 INFO Received signal 2 (SIGINT), stopping...
2023-01-27 15:30:35,161 INFO Scheduler has been shut down
2023-01-27 15:30:35,408 WARNING Exiting immediately!
2023-01-27 15:32:19,051 INFO ошибка = (1062, "Duplicate entry 'adeeer' for key 'mail'")
2023-01-27 15:32:19,223 INFO start_bot--------------------
2023-01-27 15:32:19,224 INFO Scheduler started
2023-01-27 15:33:05,912 INFO Received signal 2 (SIGINT), stopping...
2023-01-27 15:33:05,912 INFO Scheduler has been shut down
2023-01-27 15:33:06,216 WARNING Exiting immediately!
2023-01-27 15:33:08,753 INFO ошибка = (1062, "Duplicate entry 'adeeer' for key 'mail'")
2023-01-27 15:33:08,856 INFO start_bot--------------------
2023-01-27 15:33:08,858 INFO Scheduler started
2023-01-27 15:34:44,135 INFO Received signal 2 (SIGINT), stopping...
2023-01-27 15:34:44,135 INFO Scheduler has been shut down
2023-01-27 15:34:44,479 WARNING Exiting immediately!
2023-01-27 15:52:48,028 INFO ошибка = (1062, "Duplicate entry 'adeeer' for key 'mail'")
2023-01-27 15:52:48,113 INFO start_bot--------------------
2023-01-27 15:52:48,114 INFO Scheduler started
2023-01-27 15:52:59,350 INFO нераспознанный текст /start
2023-01-27 15:54:29,046 INFO Received signal 2 (SIGINT), stopping...
2023-01-27 15:54:29,046 INFO Scheduler has been shut down
2023-01-27 15:54:29,405 WARNING Exiting immediately!
2023-01-27 15:57:50,763 INFO ошибка = (1062, "Duplicate entry 'adeeer' for key 'mail'")
2023-01-27 15:57:50,884 INFO start_bot--------------------
2023-01-27 15:57:50,885 INFO Scheduler started
2023-01-27 16:02:07,654 INFO Received signal 2 (SIGINT), stopping...
2023-01-27 16:02:07,654 INFO Scheduler has been shut down
2023-01-27 16:02:07,949 WARNING Exiting immediately!
2023-01-27 16:02:10,932 INFO ошибка = (1062, "Duplicate entry 'adeeer' for key 'mail'")
2023-01-27 16:02:11,130 INFO start_bot--------------------
2023-01-27 16:02:27,752 INFO ошибка = (1062, "Duplicate entry 'adeeer' for key 'mail'")
2023-01-27 16:02:27,983 INFO start_bot--------------------
2023-01-27 16:02:27,984 INFO Scheduler started
2023-01-27 16:02:44,662 INFO нераспознанный текст да
2023-01-27 16:03:25,212 INFO Received signal 2 (SIGINT), stopping...
2023-01-27 16:03:25,212 INFO Scheduler has been shut down
2023-01-27 16:03:25,612 WARNING Exiting immediately!
2023-01-27 16:03:46,099 INFO ошибка = (1062, "Duplicate entry 'adeeer' for key 'mail'")
2023-01-27 16:03:46,234 INFO start_bot--------------------
2023-01-27 16:03:46,236 INFO Scheduler started
2023-01-27 16:08:34,071 INFO Received signal 2 (SIGINT), stopping...
2023-01-27 16:08:34,071 INFO Scheduler has been shut down
2023-01-27 16:08:34,390 WARNING Exiting immediately!
2023-01-27 16:17:57,277 INFO ошибка = (1062, "Duplicate entry 'adeeer' for key 'mail'")
2023-01-27 16:17:57,436 INFO start_bot--------------------
2023-01-27 16:17:57,437 INFO Scheduler started
2023-01-27 16:18:48,309 INFO Received signal 2 (SIGINT), stopping...
2023-01-27 16:18:48,309 INFO Scheduler has been shut down
2023-01-27 16:18:48,588 WARNING Exiting immediately!
2023-01-27 16:18:50,774 INFO ошибка = (1062, "Duplicate entry 'adeeer' for key 'mail'")
2023-01-27 16:18:50,868 INFO start_bot--------------------
2023-01-27 16:18:50,869 INFO Scheduler started
2023-01-27 16:19:19,979 INFO Received signal 2 (SIGINT), stopping...
2023-01-27 16:19:19,980 INFO Scheduler has been shut down
2023-01-27 16:19:20,651 WARNING Exiting immediately!
2023-01-27 16:26:47,409 INFO ошибка = (1062, "Duplicate entry 'adeeer' for key 'mail'")
2023-01-27 16:26:47,557 INFO start_bot--------------------
2023-01-27 16:26:47,558 INFO Scheduler started
2023-01-27 16:36:59,007 INFO Received signal 2 (SIGINT), stopping...
2023-01-27 16:36:59,008 INFO Scheduler has been shut down
2023-01-27 16:36:59,423 WARNING Exiting immediately!
2023-01-27 16:37:01,805 INFO start_bot--------------------
2023-01-27 16:37:01,806 INFO Scheduler started
2023-01-27 16:37:19,779 INFO ошибка = (1062, "Duplicate entry 'adeeer' for key 'mail'")
2023-01-27 16:42:01,684 INFO Received signal 2 (SIGINT), stopping...
2023-01-27 16:42:01,684 INFO Scheduler has been shut down
2023-01-27 16:42:01,987 WARNING Exiting immediately!
2023-01-27 16:42:04,198 INFO start_bot--------------------
2023-01-27 16:42:04,199 INFO Scheduler started
2023-01-27 16:43:45,872 INFO Received signal 2 (SIGINT), stopping...
2023-01-27 16:43:45,873 INFO Scheduler has been shut down
2023-01-27 16:43:46,121 WARNING Exiting immediately!
2023-01-27 16:43:48,090 INFO start_bot--------------------
2023-01-27 16:43:48,091 INFO Scheduler started
2023-01-27 16:45:18,758 INFO Received signal 2 (SIGINT), stopping...
2023-01-27 16:45:18,758 INFO Scheduler has been shut down
2023-01-27 16:45:19,222 WARNING Exiting immediately!
2023-01-27 16:45:25,510 INFO start_bot--------------------
2023-01-27 16:45:25,511 INFO Scheduler started
2023-01-27 17:03:32,169 INFO Received signal 2 (SIGINT), stopping...
2023-01-27 17:03:32,170 INFO Scheduler has been shut down
2023-01-27 17:03:32,360 WARNING Exiting immediately!
2023-01-27 17:03:34,682 INFO start_bot--------------------
2023-01-27 17:03:34,683 INFO Scheduler started
2023-01-27 17:06:55,650 INFO Received signal 2 (SIGINT), stopping...
2023-01-27 17:06:55,650 INFO Scheduler has been shut down
2023-01-27 17:06:55,898 WARNING Exiting immediately!
2023-01-27 17:06:58,711 INFO start_bot--------------------
2023-01-27 17:06:58,712 INFO Scheduler started
2023-01-27 17:07:09,747 ERROR No error handlers are registered, logging exception.
Traceback (most recent call last):
  File "/Library/Frameworks/Python.framework/Versions/3.11/lib/python3.11/site-packages/telegram/ext/dispatcher.py", line 557, in process_update
    handler.handle_update(update, self, check, context)
  File "/Library/Frameworks/Python.framework/Versions/3.11/lib/python3.11/site-packages/telegram/ext/conversationhandler.py", line 627, in handle_update
    new_state = handler.handle_update(update, dispatcher, check_result, context)
                ^^^^^^^^^^^^^^^^^^^^^^^^^^^^^^^^^^^^^^^^^^^^^^^^^^^^^^^^^^^^^^^^
  File "/Library/Frameworks/Python.framework/Versions/3.11/lib/python3.11/site-packages/telegram/ext/handler.py", line 199, in handle_update
    return self.callback(update, context)
           ^^^^^^^^^^^^^^^^^^^^^^^^^^^^^^
TypeError: second_response() missing 1 required positional argument: 'a'
2023-01-27 17:08:09,400 INFO Received signal 2 (SIGINT), stopping...
2023-01-27 17:08:09,400 INFO Scheduler has been shut down
2023-01-27 17:08:09,663 WARNING Exiting immediately!
2023-01-27 17:08:18,380 INFO start_bot--------------------
2023-01-27 17:08:18,381 INFO Scheduler started
2023-01-27 17:08:32,639 INFO нераспознанный текст din
2023-01-27 17:13:28,940 INFO Received signal 2 (SIGINT), stopping...
2023-01-27 17:13:28,940 INFO Scheduler has been shut down
2023-01-27 17:13:29,244 WARNING Exiting immediately!
2023-01-27 17:17:04,163 INFO start_bot--------------------
2023-01-27 17:17:04,164 INFO Scheduler started
2023-01-27 17:17:16,280 ERROR No error handlers are registered, logging exception.
Traceback (most recent call last):
  File "/Library/Frameworks/Python.framework/Versions/3.11/lib/python3.11/site-packages/telegram/ext/dispatcher.py", line 557, in process_update
    handler.handle_update(update, self, check, context)
  File "/Library/Frameworks/Python.framework/Versions/3.11/lib/python3.11/site-packages/telegram/ext/conversationhandler.py", line 660, in handle_update
    self._update_state(new_state, conversation_key)
  File "/Library/Frameworks/Python.framework/Versions/3.11/lib/python3.11/site-packages/telegram/ext/conversationhandler.py", line 685, in _update_state
    if new_state not in self.states:
       ^^^^^^^^^^^^^^^^^^^^^^^^^^^^
TypeError: unhashable type: 'list'
2023-01-27 17:22:34,855 INFO Received signal 2 (SIGINT), stopping...
2023-01-27 17:22:34,856 INFO Scheduler has been shut down
2023-01-27 17:22:35,143 WARNING Exiting immediately!
2023-01-27 17:22:37,247 INFO start_bot--------------------
2023-01-27 17:22:37,248 INFO Scheduler started
2023-01-27 17:22:47,354 ERROR No error handlers are registered, logging exception.
Traceback (most recent call last):
  File "/Library/Frameworks/Python.framework/Versions/3.11/lib/python3.11/site-packages/telegram/ext/dispatcher.py", line 557, in process_update
    handler.handle_update(update, self, check, context)
  File "/Library/Frameworks/Python.framework/Versions/3.11/lib/python3.11/site-packages/telegram/ext/conversationhandler.py", line 660, in handle_update
    self._update_state(new_state, conversation_key)
  File "/Library/Frameworks/Python.framework/Versions/3.11/lib/python3.11/site-packages/telegram/ext/conversationhandler.py", line 685, in _update_state
    if new_state not in self.states:
       ^^^^^^^^^^^^^^^^^^^^^^^^^^^^
TypeError: unhashable type: 'list'
2023-01-27 17:24:59,363 INFO Received signal 2 (SIGINT), stopping...
2023-01-27 17:24:59,364 INFO Scheduler has been shut down
2023-01-27 17:24:59,659 WARNING Exiting immediately!
2023-01-27 17:25:02,892 INFO start_bot--------------------
2023-01-27 17:25:02,893 INFO Scheduler started
2023-01-27 17:25:07,834 INFO нераспознанный текст 1
2023-01-27 17:25:15,570 ERROR No error handlers are registered, logging exception.
Traceback (most recent call last):
  File "/Library/Frameworks/Python.framework/Versions/3.11/lib/python3.11/site-packages/telegram/ext/dispatcher.py", line 557, in process_update
    handler.handle_update(update, self, check, context)
  File "/Library/Frameworks/Python.framework/Versions/3.11/lib/python3.11/site-packages/telegram/ext/conversationhandler.py", line 660, in handle_update
    self._update_state(new_state, conversation_key)
  File "/Library/Frameworks/Python.framework/Versions/3.11/lib/python3.11/site-packages/telegram/ext/conversationhandler.py", line 685, in _update_state
    if new_state not in self.states:
       ^^^^^^^^^^^^^^^^^^^^^^^^^^^^
TypeError: unhashable type: 'list'
2023-01-27 17:27:20,048 INFO Received signal 2 (SIGINT), stopping...
2023-01-27 17:27:20,050 INFO Scheduler has been shut down
2023-01-27 17:27:20,255 WARNING Exiting immediately!
2023-01-27 17:28:26,064 INFO start_bot--------------------
2023-01-27 17:28:26,065 INFO Scheduler started
2023-01-27 17:30:03,219 INFO Received signal 2 (SIGINT), stopping...
2023-01-27 17:30:03,219 INFO Scheduler has been shut down
2023-01-27 17:30:03,507 WARNING Exiting immediately!
2023-01-27 17:30:06,669 INFO start_bot--------------------
2023-01-27 17:30:06,671 INFO Scheduler started
2023-01-27 17:30:12,247 ERROR No error handlers are registered, logging exception.
Traceback (most recent call last):
  File "/Library/Frameworks/Python.framework/Versions/3.11/lib/python3.11/site-packages/telegram/ext/dispatcher.py", line 557, in process_update
    handler.handle_update(update, self, check, context)
  File "/Library/Frameworks/Python.framework/Versions/3.11/lib/python3.11/site-packages/telegram/ext/conversationhandler.py", line 660, in handle_update
    self._update_state(new_state, conversation_key)
  File "/Library/Frameworks/Python.framework/Versions/3.11/lib/python3.11/site-packages/telegram/ext/conversationhandler.py", line 685, in _update_state
    if new_state not in self.states:
       ^^^^^^^^^^^^^^^^^^^^^^^^^^^^
TypeError: unhashable type: 'list'
2023-01-27 17:31:22,303 INFO Received signal 2 (SIGINT), stopping...
2023-01-27 17:31:22,303 INFO Scheduler has been shut down
2023-01-27 17:31:22,551 WARNING Exiting immediately!
2023-01-27 17:31:25,384 INFO start_bot--------------------
2023-01-27 17:31:25,385 INFO Scheduler started
2023-01-27 17:31:36,185 ERROR No error handlers are registered, logging exception.
Traceback (most recent call last):
  File "/Library/Frameworks/Python.framework/Versions/3.11/lib/python3.11/site-packages/telegram/ext/dispatcher.py", line 557, in process_update
    handler.handle_update(update, self, check, context)
  File "/Library/Frameworks/Python.framework/Versions/3.11/lib/python3.11/site-packages/telegram/ext/conversationhandler.py", line 660, in handle_update
    self._update_state(new_state, conversation_key)
  File "/Library/Frameworks/Python.framework/Versions/3.11/lib/python3.11/site-packages/telegram/ext/conversationhandler.py", line 685, in _update_state
    if new_state not in self.states:
       ^^^^^^^^^^^^^^^^^^^^^^^^^^^^
TypeError: unhashable type: 'list'
2023-01-27 17:36:51,465 INFO Received signal 2 (SIGINT), stopping...
2023-01-27 17:36:51,465 INFO Scheduler has been shut down
2023-01-27 17:36:51,688 WARNING Exiting immediately!
2023-01-27 17:36:54,479 INFO start_bot--------------------
2023-01-27 17:36:54,480 INFO Scheduler started
2023-01-27 17:38:15,127 INFO Received signal 2 (SIGINT), stopping...
2023-01-27 17:38:15,127 INFO Scheduler has been shut down
2023-01-27 17:38:15,510 WARNING Exiting immediately!
2023-01-27 17:38:49,961 INFO start_bot--------------------
2023-01-27 17:38:49,962 INFO Scheduler started
2023-01-27 17:42:37,447 INFO Received signal 2 (SIGINT), stopping...
2023-01-27 17:42:37,447 INFO Scheduler has been shut down
2023-01-27 17:42:37,839 WARNING Exiting immediately!
2023-01-27 17:42:40,152 INFO start_bot--------------------
2023-01-27 17:42:40,152 INFO Scheduler started
2023-01-27 17:42:49,656 ERROR No error handlers are registered, logging exception.
Traceback (most recent call last):
  File "/Library/Frameworks/Python.framework/Versions/3.11/lib/python3.11/site-packages/telegram/ext/dispatcher.py", line 557, in process_update
    handler.handle_update(update, self, check, context)
  File "/Library/Frameworks/Python.framework/Versions/3.11/lib/python3.11/site-packages/telegram/ext/conversationhandler.py", line 627, in handle_update
    new_state = handler.handle_update(update, dispatcher, check_result, context)
                ^^^^^^^^^^^^^^^^^^^^^^^^^^^^^^^^^^^^^^^^^^^^^^^^^^^^^^^^^^^^^^^^
  File "/Library/Frameworks/Python.framework/Versions/3.11/lib/python3.11/site-packages/telegram/ext/handler.py", line 199, in handle_update
    return self.callback(update, context)
           ^^^^^^^^^^^^^^^^^^^^^^^^^^^^^^
TypeError: first_response() missing 1 required positional argument: 'user_var'
2023-01-27 17:43:40,340 INFO Received signal 2 (SIGINT), stopping...
2023-01-27 17:43:40,340 INFO Scheduler has been shut down
2023-01-27 17:43:40,581 WARNING Exiting immediately!
2023-01-27 17:43:42,923 INFO start_bot--------------------
2023-01-27 17:43:42,924 INFO Scheduler started
2023-01-27 18:02:06,636 INFO start_bot--------------------
2023-01-27 18:02:06,637 INFO Scheduler started
2023-01-27 18:02:20,316 ERROR No error handlers are registered, logging exception.
Traceback (most recent call last):
  File "/Library/Frameworks/Python.framework/Versions/3.11/lib/python3.11/site-packages/telegram/ext/dispatcher.py", line 557, in process_update
    handler.handle_update(update, self, check, context)
  File "/Library/Frameworks/Python.framework/Versions/3.11/lib/python3.11/site-packages/telegram/ext/conversationhandler.py", line 627, in handle_update
    new_state = handler.handle_update(update, dispatcher, check_result, context)
                ^^^^^^^^^^^^^^^^^^^^^^^^^^^^^^^^^^^^^^^^^^^^^^^^^^^^^^^^^^^^^^^^
  File "/Library/Frameworks/Python.framework/Versions/3.11/lib/python3.11/site-packages/telegram/ext/handler.py", line 199, in handle_update
    return self.callback(update, context)
           ^^^^^^^^^^^^^^^^^^^^^^^^^^^^^^
TypeError: second_response() missing 1 required positional argument: 'user_var'
2023-01-27 18:02:54,094 INFO Received signal 2 (SIGINT), stopping...
2023-01-27 18:02:54,094 INFO Scheduler has been shut down
2023-01-27 18:02:54,350 WARNING Exiting immediately!
2023-01-27 18:02:58,715 INFO start_bot--------------------
2023-01-27 18:02:58,716 INFO Scheduler started
2023-01-27 18:29:11,869 INFO Received signal 2 (SIGINT), stopping...
2023-01-27 18:29:11,870 INFO Scheduler has been shut down
2023-01-27 18:29:12,075 WARNING Exiting immediately!
2023-01-27 18:39:46,152 INFO start_bot--------------------
2023-01-27 18:39:46,152 INFO Scheduler started
2023-01-27 18:43:20,682 INFO Received signal 2 (SIGINT), stopping...
2023-01-27 18:43:20,682 INFO Scheduler has been shut down
2023-01-27 18:43:20,897 WARNING Exiting immediately!
2023-01-27 18:43:31,406 INFO start_bot--------------------
2023-01-27 18:43:31,406 INFO Scheduler started
2023-01-27 18:44:06,063 INFO Received signal 2 (SIGINT), stopping...
2023-01-27 18:44:06,064 INFO Scheduler has been shut down
2023-01-27 18:44:06,296 WARNING Exiting immediately!
2023-01-27 18:44:11,413 INFO start_bot--------------------
2023-01-27 18:44:11,414 INFO Scheduler started
2023-01-27 18:48:56,988 INFO Received signal 2 (SIGINT), stopping...
2023-01-27 18:48:56,988 INFO Scheduler has been shut down
2023-01-27 18:48:57,306 WARNING Exiting immediately!
2023-01-27 18:49:00,257 INFO start_bot--------------------
2023-01-27 18:49:00,258 INFO Scheduler started
2023-01-27 18:53:18,013 INFO Received signal 2 (SIGINT), stopping...
2023-01-27 18:53:18,013 INFO Scheduler has been shut down
2023-01-27 18:53:18,340 WARNING Exiting immediately!
2023-01-27 18:53:21,870 INFO start_bot--------------------
2023-01-27 18:53:21,872 INFO Scheduler started
2023-01-27 18:57:25,756 INFO Received signal 2 (SIGINT), stopping...
2023-01-27 18:57:25,756 INFO Scheduler has been shut down
2023-01-27 18:57:25,981 WARNING Exiting immediately!
2023-01-27 18:57:30,157 INFO start_bot--------------------
2023-01-27 18:57:30,158 INFO Scheduler started
2023-01-27 19:00:28,752 INFO Received signal 2 (SIGINT), stopping...
2023-01-27 19:00:28,752 INFO Scheduler has been shut down
2023-01-27 19:00:28,960 WARNING Exiting immediately!
2023-01-27 19:00:36,195 INFO start_bot--------------------
2023-01-27 19:00:36,196 INFO Scheduler started
2023-01-27 19:03:48,369 INFO Received signal 2 (SIGINT), stopping...
2023-01-27 19:03:48,370 INFO Scheduler has been shut down
2023-01-27 19:03:48,833 WARNING Exiting immediately!
2023-01-27 19:03:56,389 INFO start_bot--------------------
2023-01-27 19:03:56,391 INFO Scheduler started
2023-01-27 19:04:59,224 INFO Received signal 2 (SIGINT), stopping...
2023-01-27 19:04:59,224 INFO Scheduler has been shut down
2023-01-27 19:04:59,568 WARNING Exiting immediately!
2023-01-27 19:10:30,727 INFO start_bot--------------------
2023-01-27 19:10:30,728 INFO Scheduler started
2023-01-27 19:10:47,350 INFO нераспознанный текст w
2023-01-27 19:12:26,692 INFO Received signal 2 (SIGINT), stopping...
2023-01-27 19:12:26,692 INFO Scheduler has been shut down
2023-01-27 19:12:26,912 WARNING Exiting immediately!
2023-01-27 19:12:29,151 INFO start_bot--------------------
2023-01-27 19:12:29,152 INFO Scheduler started
2023-01-27 19:13:39,237 INFO Received signal 2 (SIGINT), stopping...
2023-01-27 19:13:39,237 INFO Scheduler has been shut down
2023-01-27 19:13:39,452 WARNING Exiting immediately!
2023-01-27 19:13:41,291 INFO start_bot--------------------
2023-01-27 19:13:41,292 INFO Scheduler started
2023-01-27 19:15:04,890 INFO Received signal 2 (SIGINT), stopping...
2023-01-27 19:15:04,891 INFO Scheduler has been shut down
2023-01-27 19:15:05,226 WARNING Exiting immediately!
2023-01-27 19:15:15,110 INFO start_bot--------------------
2023-01-27 19:15:15,111 INFO Scheduler started
2023-01-27 19:18:12,941 INFO Received signal 2 (SIGINT), stopping...
2023-01-27 19:18:12,942 INFO Scheduler has been shut down
2023-01-27 19:18:13,341 WARNING Exiting immediately!
2023-01-27 19:18:15,748 INFO start_bot--------------------
2023-01-27 19:18:15,749 INFO Scheduler started
2023-01-27 19:20:02,578 INFO Received signal 2 (SIGINT), stopping...
2023-01-27 19:20:02,579 INFO Scheduler has been shut down
2023-01-27 19:20:02,849 WARNING Exiting immediately!
2023-01-27 19:20:05,448 INFO start_bot--------------------
2023-01-27 19:20:05,449 INFO Scheduler started
2023-01-27 19:21:13,288 INFO Received signal 2 (SIGINT), stopping...
2023-01-27 19:21:13,289 INFO Scheduler has been shut down
2023-01-27 19:21:13,503 WARNING Exiting immediately!
2023-01-27 19:21:15,936 INFO start_bot--------------------
2023-01-27 19:21:15,937 INFO Scheduler started
2023-01-27 19:23:30,629 INFO Received signal 2 (SIGINT), stopping...
2023-01-27 19:23:30,629 INFO Scheduler has been shut down
2023-01-27 19:23:30,868 WARNING Exiting immediately!
2023-01-27 19:23:36,565 INFO start_bot--------------------
2023-01-27 19:23:36,566 INFO Scheduler started
2023-01-27 19:34:45,146 INFO Received signal 2 (SIGINT), stopping...
2023-01-27 19:34:45,148 INFO Scheduler has been shut down
2023-01-27 19:34:45,385 WARNING Exiting immediately!
2023-01-27 19:35:21,586 INFO start_bot--------------------
2023-01-27 19:35:21,587 INFO Scheduler started
2023-01-27 19:37:14,686 INFO Received signal 2 (SIGINT), stopping...
2023-01-27 19:37:14,686 INFO Scheduler has been shut down
2023-01-27 19:37:14,917 WARNING Exiting immediately!
2023-01-27 19:37:21,234 INFO start_bot--------------------
2023-01-27 19:37:21,236 INFO Scheduler started
2023-01-27 19:38:27,571 INFO Received signal 2 (SIGINT), stopping...
2023-01-27 19:38:27,571 INFO Scheduler has been shut down
2023-01-27 19:38:27,795 WARNING Exiting immediately!
2023-01-27 19:38:30,238 INFO start_bot--------------------
2023-01-27 19:38:30,239 INFO Scheduler started
2023-01-27 19:39:05,377 INFO Received signal 2 (SIGINT), stopping...
2023-01-27 19:39:05,378 INFO Scheduler has been shut down
2023-01-27 19:39:05,592 WARNING Exiting immediately!
2023-01-27 23:12:33,715 INFO start_bot--------------------
2023-01-27 23:12:33,718 INFO Scheduler started
2023-01-27 23:14:59,472 INFO Received signal 2 (SIGINT), stopping...
2023-01-27 23:14:59,472 INFO Scheduler has been shut down
2023-01-27 23:15:03,409 WARNING Exiting immediately!
2023-01-27 23:15:06,413 INFO start_bot--------------------
2023-01-27 23:15:06,413 INFO Scheduler started
2023-01-27 23:20:52,806 INFO Received signal 2 (SIGINT), stopping...
2023-01-27 23:20:52,808 INFO Scheduler has been shut down
2023-01-27 23:20:53,252 WARNING Exiting immediately!
2023-01-27 23:22:09,730 INFO start_bot--------------------
2023-01-27 23:22:09,731 INFO Scheduler started
2023-01-27 23:23:02,225 INFO Received signal 2 (SIGINT), stopping...
2023-01-27 23:23:02,225 INFO Scheduler has been shut down
2023-01-27 23:23:02,513 WARNING Exiting immediately!
2023-01-27 23:23:09,358 INFO start_bot--------------------
2023-01-27 23:23:09,359 INFO Scheduler started
2023-01-27 23:24:55,285 INFO Received signal 2 (SIGINT), stopping...
2023-01-27 23:24:55,286 INFO Scheduler has been shut down
2023-01-27 23:24:55,573 WARNING Exiting immediately!
2023-01-28 00:35:12,737 INFO start_bot--------------------
2023-01-28 00:35:12,740 INFO Scheduler started
2023-01-28 00:38:26,160 INFO Received signal 2 (SIGINT), stopping...
2023-01-28 00:38:26,162 INFO Scheduler has been shut down
2023-01-28 00:38:26,544 WARNING Exiting immediately!
2023-01-28 00:38:36,298 INFO start_bot--------------------
2023-01-28 00:38:36,299 INFO Scheduler started
2023-01-28 00:47:37,212 INFO Received signal 2 (SIGINT), stopping...
2023-01-28 00:47:37,214 INFO Scheduler has been shut down
2023-01-28 00:47:37,507 WARNING Exiting immediately!
2023-01-28 01:00:30,375 INFO start_bot--------------------
2023-01-28 01:00:30,376 INFO Scheduler started
2023-01-28 01:00:59,237 INFO 203: пользователь 642411623 запрашивал данные words : результат ваш запрос: 30
2023-01-28 01:02:47,217 INFO Received signal 2 (SIGINT), stopping...
2023-01-28 01:02:47,217 INFO Scheduler has been shut down
2023-01-28 01:02:47,512 WARNING Exiting immediately!
2023-01-28 01:02:50,023 INFO start_bot--------------------
2023-01-28 01:02:50,024 INFO Scheduler started
2023-01-28 01:02:58,950 INFO 203: пользователь <b>642411623</b> запрашивал данные words : результат ваш запрос: 30
2023-01-28 01:06:05,754 INFO нераспознанный текст d
2023-01-28 01:09:31,407 INFO Received signal 2 (SIGINT), stopping...
2023-01-28 01:09:31,407 INFO Scheduler has been shut down
2023-01-28 01:09:33,767 WARNING Exiting immediately!
2023-01-28 01:09:36,528 INFO start_bot--------------------
2023-01-28 01:09:36,529 INFO Scheduler started
2023-01-28 01:09:54,001 INFO 203: пользователь <b>642411623</b> запрашивал данные words : результат ваш запрос: 30
2023-01-28 01:19:44,830 INFO 203: пользователь <b>642411623</b> запрашивал данные words : результат ваш запрос: 30
2023-01-28 01:21:09,924 INFO Received signal 2 (SIGINT), stopping...
2023-01-28 01:21:09,925 INFO Scheduler has been shut down
2023-01-28 01:21:10,116 WARNING Exiting immediately!
